Workbook

Sheet summary
B1: Headcount | C1: Rice count | D1: 小食 count
A2: 黃偉安 | B2: 1 | C2: -
A3: 何家騏 | B3: 1 | C3: -
A4: 朱家聰 | B4: 1 | C4: -
A5: 袁可秀 | B5: 1 | C5: -
A6: 品牌推廣 | B6: 6 | C6: 6
A7: 嘉賓接待 | B7: 13 | C7: 7
A8: 秘書處 | B8: 10 | C8: 1
A9: 救傷 | B9: 8 | C9: 8
A10: 張佳良 | B10: 1 | C10: -
A11: 典禮 | B11: 9 | C11: 9
A12: 會操 | B12: 30 | C12: - | D12: 30
A13: 服務 | B13: 14 | C13: 13
A14: 協調 | B14: 17 | C14: 15
A15: 行政 | B15: 25 | C15: 16 | D15: 8
A16: ST | B16: 137 | C16: 75 | D16: 38 | E16: 113
A18: A1 Core | B18: 7 | C18: 6
A19: A2 機電1 | B19: 2 | C19: 2
A20: A3 機電2 | B20: 3 | C20: 3
A21: A4 機電3 | B21: 6 | C21: 5
A22: A5 機電4 | B22: 5 | C22: 5
A23: A6 Police-反恐 | B23: 4 | C23: -
A24: A7 Police-網絡 | B24: 4 | C24: -
A25: A8 Police-NB | B25: 2 | C25: 2
A26: A9 Police-毒品調查 | B26: 4 | C26: 4
A27: A10 Police-國安 | B27: 5 | C27: 5
A28: A11 Police-交通 | B28: 3 | C28: 3
A29: A12 Police-鑑證 | B29: 5 | C29: 5
A30: B1 青年聯會 | B30: 4 | C30: 3
A31: B2 箭會 | B31: 5 | C31: 5
A32: B3 VentureC | B32: 6 | C32: 6
A33: C1 槍會 | B33: 4 | C33: -
A34: C2 Air | B34: 7 | C34: 7
A35: C3 航天學會 | B35: 14 | C35: 14
A36: C4 無人機 | B36: 19 | C36: - | D36: 18
A37: D4 WCH-社參 1 | B37: 6 | C37: 6
A38: D5 WCH-社參 2 | B38: 6 | C38: 6
A39: E1 VIC-精神健康 | B39: 5 | C39: 5
A40: E2 VIC-公共衛生 | B40: 5 | C40: 5
A41: E3 Listening Ear | B41: 2 | C41: 2
...

Sheet data
B1: unit | C1: name | F1: rice
A2: 1 | B2: 品牌推廣 | C2: 何嘉駿 | D2: B 鹹蛋蒸肉餅飯 配菜 | E2: =LEFT(D2) -> B | F2: =IF(E2="A","A 牛腩飯",if(E2="B","B 肉餅飯",if(E2="C","C 雞脾飯",if(E2="D","D 素飯",if(E2="R","午餐一份",""))))) -> B 肉餅飯
A3: 2 | B3: 品牌推廣 | C3: 李沛豪 | D3: A 柱侯蘿蔔牛腩飯 配菜 | E3: =LEFT(D3) -> A | F3: =IF(E3="A","A 牛腩飯",if(E3="B","B 肉餅飯",if(E3="C","C 雞脾飯",if(E3="D","D 素飯",if(E3="R","午餐一份",""))))) -> A 牛腩飯
A4: 3 | B4: 品牌推廣 | C4: 林耀鏘 | D4: C 滷水雞髀拼紅腸飯 配菜 | E4: =LEFT(D4) -> C | F4: =IF(E4="A","A 牛腩飯",if(E4="B","B 肉餅飯",if(E4="C","C 雞脾飯",if(E4="D","D 素飯",if(E4="R","午餐一份",""))))) -> C 雞脾飯
A5: 4 | B5: 品牌推廣 | C5: 黃俊強 | D5: B 鹹蛋蒸肉餅飯 配菜 | E5: =LEFT(D5) -> B | F5: =IF(E5="A","A 牛腩飯",if(E5="B","B 肉餅飯",if(E5="C","C 雞脾飯",if(E5="D","D 素飯",if(E5="R","午餐一份",""))))) -> B 肉餅飯
A6: 5 | B6: 品牌推廣 | C6: 徐士奇 | D6: A 柱侯蘿蔔牛腩飯 配菜 | E6: =LEFT(D6) -> A | F6: =IF(E6="A","A 牛腩飯",if(E6="B","B 肉餅飯",if(E6="C","C 雞脾飯",if(E6="D","D 素飯",if(E6="R","午餐一份",""))))) -> A 牛腩飯
A7: 6 | B7: 品牌推廣 | C7: 陳鈞瀚 | D7: C 滷水雞髀拼紅腸飯 配菜 | E7: =LEFT(D7) -> C | F7: =IF(E7="A","A 牛腩飯",if(E7="B","B 肉餅飯",if(E7="C","C 雞脾飯",if(E7="D","D 素飯",if(E7="R","午餐一份",""))))) -> C 雞脾飯
A8: 7 | B8: 嘉賓接待 | C8: 楊焯熹 | D8: A 柱侯蘿蔔牛腩飯 配菜 | E8: =LEFT(D8) -> A | F8: =IF(E8="A","A 牛腩飯",if(E8="B","B 肉餅飯",if(E8="C","C 雞脾飯",if(E8="D","D 素飯",if(E8="R","午餐一份",""))))) -> A 牛腩飯
A9: 8 | B9: 嘉賓接待 | C9: 梁喆 | D9: A 柱侯蘿蔔牛腩飯 配菜 | E9: =LEFT(D9) -> A | F9: =IF(E9="A","A 牛腩飯",if(E9="B","B 肉餅飯",if(E9="C","C 雞脾飯",if(E9="D","D 素飯",if(E9="R","午餐一份",""))))) -> A 牛腩飯
A10: 9 | B10: 嘉賓接待 | C10: 袁頌文 | D10: D (素)翠玉瓜雲耳炒野菌 | E10: =LEFT(D10) -> D | F10: =IF(E10="A","A 牛腩飯",if(E10="B","B 肉餅飯",if(E10="C","C 雞脾飯",if(E10="D","D 素飯",if(E10="R","午餐一份",""))))) -> D 素飯
A11: 10 | B11: 嘉賓接待 | C11: 曾澤霖 | D11: A 柱侯蘿蔔牛腩飯 配菜 | E11: =LEFT(D11) -> A | F11: =IF(E11="A","A 牛腩飯",if(E11="B","B 肉餅飯",if(E11="C","C 雞脾飯",if(E11="D","D 素飯",if(E11="R","午餐一份",""))))) -> A 牛腩飯
A12: 11 | B12: 嘉賓接待 | C12: 關駿禧 | D12: C 滷水雞髀拼紅腸飯 配菜 | E12: =LEFT(D12) -> C | F12: =IF(E12="A","A 牛腩飯",if(E12="B","B 肉餅飯",if(E12="C","C 雞脾飯",if(E12="D","D 素飯",if(E12="R","午餐一份",""))))) -> C 雞脾飯
A13: 12 | B13: 嘉賓接待 | C13: 黃竣暉 | D13: B 鹹蛋蒸肉餅飯 配菜 | E13: =LEFT(D13) -> B | F13: =IF(E13="A","A 牛腩飯",if(E13="B","B 肉餅飯",if(E13="C","C 雞脾飯",if(E13="D","D 素飯",if(E13="R","午餐一份",""))))) -> B 肉餅飯
... A82: 81 | B82: A1 Core | C82: 李庭甄 | D82: Random | E82: =LEFT(D82) -> R | F82: =IF(E82="A","A 牛腩飯",if(E82="B","B 肉餅飯",if(E82="C","C 雞脾飯",if(E82="D","D 素飯",if(E82="R","午餐一份",""))))) -> 午餐一份
A83: 82 | B83: A2 機電1 | D83: Random | E83: =LEFT(D83) -> R | F83: =IF(E83="A","A 牛腩飯",if(E83="B","B 肉餅飯",if(E83="C","C 雞脾飯",if(E83="D","D 素飯",if(E83="R","午餐一份",""))))) -> 午餐一份
A84: 83 | B84: A2 機電1 | D84: Random | E84: =LEFT(D84) -> R | F84: =IF(E84="A","A 牛腩飯",if(E84="B","B 肉餅飯",if(E84="C","C 雞脾飯",if(E84="D","D 素飯",if(E84="R","午餐一份",""))))) -> 午餐一份
A85: 84 | B85: A3 機電2 | D85: Random | E85: =LEFT(D85) -> R | F85: =IF(E85="A","A 牛腩飯",if(E85="B","B 肉餅飯",if(E85="C","C 雞脾飯",if(E85="D","D 素飯",if(E85="R","午餐一份",""))))) -> 午餐一份
A86: 85 | B86: A3 機電2 | D86: Random | E86: =LEFT(D86) -> R | F86: =IF(E86="A","A 牛腩飯",if(E86="B","B 肉餅飯",if(E86="C","C 雞脾飯",if(E86="D","D 素飯",if(E86="R","午餐一份",""))))) -> 午餐一份
A87: 86 | B87: A3 機電2 | D87: Random | E87: =LEFT(D87) -> R | F87: =IF(E87="A","A 牛腩飯",if(E87="B","B 肉餅飯",if(E87="C","C 雞脾飯",if(E87="D","D 素飯",if(E87="R","午餐一份",""))))) -> 午餐一份
A88: 87 | B88: A4 機電3 | D88: Random | E88: =LEFT(D88) -> R | F88: =IF(E88="A","A 牛腩飯",if(E88="B","B 肉餅飯",if(E88="C","C 雞脾飯",if(E88="D","D 素飯",if(E88="R","午餐一份",""))))) -> 午餐一份
A89: 88 | B89: A4 機電3 | D89: Random | E89: =LEFT(D89) -> R | F89: =IF(E89="A","A 牛腩飯",if(E89="B","B 肉餅飯",if(E89="C","C 雞脾飯",if(E89="D","D 素飯",if(E89="R","午餐一份",""))))) -> 午餐一份
A90: 89 | B90: A4 機電3 | D90: Random | E90: =LEFT(D90) -> R | F90: =IF(E90="A","A 牛腩飯",if(E90="B","B 肉餅飯",if(E90="C","C 雞脾飯",if(E90="D","D 素飯",if(E90="R","午餐一份",""))))) -> 午餐一份
A91: 90 | B91: A4 機電3 | D91: Random | E91: =LEFT(D91) -> R | F91: =IF(E91="A","A 牛腩飯",if(E91="B","B 肉餅飯",if(E91="C","C 雞脾飯",if(E91="D","D 素飯",if(E91="R","午餐一份",""))))) -> 午餐一份
A92: 91 | B92: A4 機電3 | D92: Random | E92: =LEFT(D92) -> R | F92: =IF(E92="A","A 牛腩飯",if(E92="B","B 肉餅飯",if(E92="C","C 雞脾飯",if(E92="D","D 素飯",if(E92="R","午餐一份",""))))) -> 午餐一份
A93: 92 | B93: A5 機電4 | D93: Random | E93: =LEFT(D93) -> R | F93: =IF(E93="A","A 牛腩飯",if(E93="B","B 肉餅飯",if(E93="C","C 雞脾飯",if(E93="D","D 素飯",if(E93="R","午餐一份",""))))) -> 午餐一份
A94: 93 | B94: A5 機電4 | D94: Random | E94: =LEFT(D94) -> R | F94: =IF(E94="A","A 牛腩飯",if(E94="B","B 肉餅飯",if(E94="C","C 雞脾飯",if(E94="D","D 素飯",if(E94="R","午餐一份",""))))) -> 午餐一份
... A97: 96 | B97: A5 機電4 | D97: Random | E97: =LEFT(D97) -> R | F97: =IF(E97="A","A 牛腩飯",if(E97="B","B 肉餅飯",if(E97="C","C 雞脾飯",if(E97="D","D 素飯",if(E97="R","午餐一份",""))))) -> 午餐一份
A98: 97 | B98: A8 Police-NB | C98: NA | D98: Random | E98: =LEFT(D98) -> R | F98: =IF(E98="A","A 牛腩飯",if(E98="B","B 肉餅飯",if(E98="C","C 雞脾飯",if(E98="D","D 素飯",if(E98="R","午餐一份",""))))) -> 午餐一份
A99: 98 | B99: A8 Police-NB | C99: NA | D99: Random | E99: =LEFT(D99) -> R | F99: =IF(E99="A","A 牛腩飯",if(E99="B","B 肉餅飯",if(E99="C","C 雞脾飯",if(E99="D","D 素飯",if(E99="R","午餐一份",""))))) -> 午餐一份
A100: 99 | B100: A9 Police-毒品調查 | C100: NA | D100: Random | E100: =LEFT(D100) -> R | F100: =IF(E100="A","A 牛腩飯",if(E100="B","B 肉餅飯",if(E100="C","C 雞脾飯",if(E100="D","D 素飯",if(E100="R","午餐一份",""))))) -> 午餐一份
A101: 100 | B101: A9 Police-毒品調查 | C101: NA | D101: Random | E101: =LEFT(D101) -> R | F101: =IF(E101="A","A 牛腩飯",if(E101="B","B 肉餅飯",if(E101="C","C 雞脾飯",if(E101="D","D 素飯",if(E101="R","午餐一份",""))))) -> 午餐一份
A102: 101 | B102: A9 Police-毒品調查 | C102: NA | D102: Random | E102: =LEFT(D102) -> R | F102: =IF(E102="A","A 牛腩飯",if(E102="B","B 肉餅飯",if(E102="C","C 雞脾飯",if(E102="D","D 素飯",if(E102="R","午餐一份",""))))) -> 午餐一份
A103: 102 | B103: A9 Police-毒品調查 | C103: NA | D103: Random | E103: =LEFT(D103) -> R | F103: =IF(E103="A","A 牛腩飯",if(E103="B","B 肉餅飯",if(E103="C","C 雞脾飯",if(E103="D","D 素飯",if(E103="R","午餐一份",""))))) -> 午餐一份
A104: 103 | B104: A10 Police-國安 | C104: NA | D104: Random | E104: =LEFT(D104) -> R | F104: =IF(E104="A","A 牛腩飯",if(E104="B","B 肉餅飯",if(E104="C","C 雞脾飯",if(E104="D","D 素飯",if(E104="R","午餐一份",""))))) -> 午餐一份
A105: 104 | B105: A10 Police-國安 | C105: NA | D105: Random | E105: =LEFT(D105) -> R | F105: =IF(E105="A","A 牛腩飯",if(E105="B","B 肉餅飯",if(E105="C","C 雞脾飯",if(E105="D","D 素飯",if(E105="R","午餐一份",""))))) -> 午餐一份
A106: 105 | B106: A10 Police-國安 | C106: NA | D106: Random | E106: =LEFT(D106) -> R | F106: =IF(E106="A","A 牛腩飯",if(E106="B","B 肉餅飯",if(E106="C","C 雞脾飯",if(E106="D","D 素飯",if(E106="R","午餐一份",""))))) -> 午餐一份
A107: 106 | B107: A10 Police-國安 | C107: NA | D107: Random | E107: =LEFT(D107) -> R | F107: =IF(E107="A","A 牛腩飯",if(E107="B","B 肉餅飯",if(E107="C","C 雞脾飯",if(E107="D","D 素飯",if(E107="R","午餐一份",""))))) -> 午餐一份
A108: 107 | B108: A10 Police-國安 | C108: NA | D108: Random | E108: =LEFT(D108) -> R | F108: =IF(E108="A","A 牛腩飯",if(E108="B","B 肉餅飯",if(E108="C","C 雞脾飯",if(E108="D","D 素飯",if(E108="R","午餐一份",""))))) -> 午餐一份
A109: 108 | B109: A11 Police-交通 | C109: NA | D109: Random | E109: =LEFT(D109) -> R | F109: =IF(E109="A","A 牛腩飯",if(E109="B","B 肉餅飯",if(E109="C","C 雞脾飯",if(E109="D","D 素飯",if(E109="R","午餐一份",""))))) -> 午餐一份
... A119: 118 | B119: B1 青年聯會 | C119: NA | D119: Random | E119: =LEFT(D119) -> R | F119: =IF(E119="A","A 牛腩飯",if(E119="B","B 肉餅飯",if(E119="C","C 雞脾飯",if(E119="D","D 素飯",if(E119="R","午餐一份",""))))) -> 午餐一份
...

Sheet 其他
B1: 組別 | C1: 中文姓名 | D1: 童軍職位 (L,R,V,S) | E1: 所屬旅團 (地域幹部請填寫職位) | F1: 午餐選擇 | G1: 電郵地址(寄發感謝狀用) | H1: Remarks | I1: For core committee only
A2: 1 | B2: 管理 | C2: 黃偉安 | D2: L | E2: DRC | F2: 嘉賓自助午餐(只限總監級/副主席) | G2: edwardwong@hkirscout.org.hk | I2: 顧問
A3: 2 | B3: 管理 | C3: 何家騏 | D3: L | E3: ARC | F3: 嘉賓自助午餐(只限總監級/副主席) | G3: dominicho@hkirscout.org.hk | I3: 顧問
A4: 3 | B4: 管理 | C4: 朱家聰 | D4: L | E4: ARC | F4: 嘉賓自助午餐(只限總監級/副主席) | G4: chukachung@gmail.com | I4: 主席
A5: 4 | B5: 管理 | C5: 袁可秀 | D5: L | E5: 206HKG | F5: 嘉賓自助午餐(只限總監級/副主席) | G5: allisonyuen@yahoo.com.hk | I5: 執行副主席
A6: 5 | B6: 品牌推廣 | C6: 何嘉駿 | D6: L | E6: ADC/VIC | F6: B 鹹蛋蒸肉餅飯 配菜 | I6: 副主席（品牌推廣）
A7: 6 | B7: 品牌推廣 | C7: 李沛豪 | D7: L | E7: CHW | F7: A 柱侯蘿蔔牛腩飯 配菜 | I7: 宣傳主任
A8: 7 | B8: 品牌推廣 | C8: 林耀鏘 | D8: L | E8: VIC | F8: C 滷水雞髀拼紅腸飯 配菜 | I8: 拍攝/攝錄統籌主任
A9: 8 | B9: 品牌推廣 | C9: 黃俊強 | D9: L | F9: B 鹹蛋蒸肉餅飯 配菜 | I9: 設計主任
A10: 9 | B10: 品牌推廣 | C10: 徐士奇 | D10: L | E10: VIC | F10: A 柱侯蘿蔔牛腩飯 配菜
A11: 10 | B11: 品牌推廣 | C11: 陳鈞瀚 | D11: L | E11: VIC | F11: C 滷水雞髀拼紅腸飯 配菜
A12: 11 | B12: 嘉賓接待 | C12: 曾麗珊 | D12: L | E12: ARC | F12: 午餐時間無需當值 | I12: 副主席（嘉賓接待）
A13: 12 | B13: 嘉賓接待 | C13: 張嘉政 | D13: L | E13: RHQC | F13: 嘉賓自助午餐(只限總監級/副主席) | G13: jackcheung@hkirscout.org.hk | I13: 總主任（嘉賓接待）
A14: 13 | B14: 嘉賓接待 | C14: 黃培芳 | D14: L | E14: RHQC | F14: 嘉賓自助午餐(只限總監級/副主席) | G14: teresawg1021@gmail.com | I14: 嘉賓接待主任
A15: 14 | B15: 嘉賓接待 | C15: 張敬浩 | D15: L | E15: ARHQC | F15: 嘉賓自助午餐(只限總監級/副主席) | G15: marscheung@hkirscout.org.hk | I15: 交通主任
A16: 15 | B16: 嘉賓接待 | C16: 朱浩銘 | D16: L | E16: ARHQC | F16: 嘉賓自助午餐(只限總監級/副主席) | G16: minghochu2004@yahoo.com.hk | I16: 嘉賓支援主任
A17: 16 | B17: 嘉賓接待 | C17: 楊焯熹 | D17: VS | E17: 186HKG | F17: A 柱侯蘿蔔牛腩飯 配菜
A18: 17 | B18: 嘉賓接待 | C18: 梁喆 | D18: L | E18: HKIR RS | F18: A 柱侯蘿蔔牛腩飯 配菜
A19: 18 | B19: 嘉賓接待 | C19: 袁頌文 | D19: L | E19: HKIR RS | F19: D (素)翠玉瓜雲耳炒野菌
A20: 19 | B20: 嘉賓接待 | C20: 曾澤霖 | D20: L | E20: BP | F20: A 柱侯蘿蔔牛腩飯 配菜
A21: 20 | B21: 嘉賓接待 | C21: 關駿禧 | D21: L | E21: 7HKG | F21: C 滷水雞髀拼紅腸飯 配菜
A22: 21 | B22: 嘉賓接待 | C22: 黃竣暉 | D22: L | E22: HKIR RS | F22: B 鹹蛋蒸肉餅飯 配菜
A23: 22 | B23: 嘉賓接待 | C23: 李朗僖 | D23: VS | E23: 256 | F23: B 鹹蛋蒸肉餅飯 配菜
A24: 23 | B24: 嘉賓接待 | C24: 楊國榮 | D24: L | E24: WCH | F24: 嘉賓自助午餐(只限總監級/副主席)
A25: 24 | B25: 其他 | C25: 救傷1 | D25: L | E25: NGO | F25: Random
A26: 25 | B26: 其他 | C26: 救傷2 | D26: L | E26: NGO | F26: Random
A27: 26 | B27: 其他 | C27: 救傷3 | D27: L | E27: NGO | F27: Random
A28: 27 | B28: 其他 | C28: 救傷4 | D28: L | E28: NGO | F28: Random
A29: 28 | B29: 其他 | C29: 救傷5 | D29: L | E29: NGO | F29: Random
A30: 29 | B30: 其他 | C30: 救傷6 | D30: L | E30: NGO | F30: Random
A31: 30 | B31: 其他 | C31: 救傷7 | D31: L | E31: NGO | F31: Random
A32: 31 | B32: 其他 | C32: 救傷8 | D32: L | E32: NGO | F32: Random
A33: 32 | B33: 秘書處 | C33: 譚健祥 | D33: L | E33: HKIR | F33: 嘉賓自助午餐(只限總監級/副主席)
A34: 33 | B34: 秘書處 | C34: 何家耀 | D34: L | E34: HKIR | F34: A 柱侯蘿蔔牛腩飯 配菜
D35: A | E35: =COUNTIF(F:F,"A*") -> 6
D36: B | E36: =COUNTIF(F:F,"B*") -> 4
D37: C | E37: =COUNTIF(F:F,"C*") -> 3
D38: D | E38: =COUNTIF(F:F,"D*") -> 1
D39: Random | E39: =COUNTIF(F:F,"Random") -> 8
D40: Buffet | E40: =COUNTIF(F:F,"嘉*") -> 10
...

Sheet 節目
B1: 組別 | C1: 中文姓名 | D1: 童軍職位 (L,R,V,S) | E1: 所屬旅團 (地域幹部請填寫職位) | F1: 午餐選擇 | G1: 電郵地址(寄發感謝狀用) | H1: Booth No./Name | I1: For core committee only | L1: Abb | M1: Lunch | N1: 人
A2: 1 | B2: 主題節目 | C2: 周恒晉 | D2: L | E2: RHQC | F2: Random | H2: A1 Core | I2: 副主席（主題節目） | J2: A1 | K2: 節目組總部 | L2: A1 Core | M2: 7 | N2: =COUNTIF(H:H,L2) -> 7 | P2: 港島第161旅 深資童軍 高敏儀 | Q2: 港島第161旅 深資童軍 何卓茵 | R2: 港島第161旅 深資童軍 何祉鋆 | S2: 港島第161旅 深資童軍 伍恩孝 | T2: 港島第161旅 深資童軍 李漢宏
A3: 2 | B3: 主題節目 | C3: 仇紹謙 | D3: L | E3: ADC/HKW | F3: 嘉賓自助午餐(只限總監級) | H3: A1 Core | I3: 總主任（主題節目） | J3: A2 | K3: 積極公民工作坊 - 機電1 | L3: A2 機電1 | M3: 2 | N3: =COUNTIF(H:H,L3) -> 2
A4: 3 | B4: 主題節目 | C4: 何令勤 | D4: L | E4: HKIR | F4: Random | H4: A1 Core | I4: 節目主任 | J4: A3 | K4: 積極公民工作坊 - 機電2 | L4: A3 機電2 | M4: 3 | N4: =COUNTIF(H:H,L4) -> 3
A5: 4 | B5: 主題節目 | C5: 陳鋑羲 | D5: L | F5: Random | H5: A1 Core | I5: 節目主任 | J5: A4 | K5: 積極公民工作坊 - 機電3 | L5: A4 機電3 | M5: 5 | N5: =COUNTIF(H:H,L5) -> 6
A6: 5 | B6: 主題節目 | C6: 張宏剛 | D6: L | E6: ADC/HKS | F6: Random | H6: A1 Core | I6: 節目主任 | J6: A5 | K6: 積極公民工作坊 - 機電4 | L6: A5 機電4 | M6: 5 | N6: =COUNTIF(H:H,L6) -> 5
A7: 6 | B7: 主題節目 | C7: 羅卓華 | D7: L | F7: Random | H7: A1 Core | I7: 節目主任 | J7: A6 | K7: 香港警務處 - 跨部門反恐專責組(ICTU) 1100前完成setup | L7: A6 Police-反恐 | M7: Nil | N7: =COUNTIF(H:H,L7) -> 4
A8: 7 | B8: 主題節目 | C8: 李庭甄 | D8: L | F8: Random | H8: A1 Core | I8: 節目主任 | J8: A7 | K8: 香港警務處 - 網絡安全及科技罪案調查科(CSTCB) 1300前完成setup | L8: A7 Police-網絡 | M8: NIl | N8: =COUNTIF(H:H,L8) -> 4
A9: 8 | B9: 主題節目 | C9: 鄭筠頤 | D9: V | E9: 1178EKG | F9: Random | H9: A2 機電1 | J9: A8 | K9: 香港警務處 - 毒品調查科(NB) | L9: A8 Police-NB | M9: =N9 -> 2 | N9: =COUNTIF(H:H,L9) -> 2
A10: 9 | B10: 主題節目 | C10: 堵祺銘 | D10: R | E10: 66HKG | F10: Random | H10: A2 機電1 | J10: A9 | K10: 香港警務處 - 毒品調查科(NB) | L10: A9 Police-毒品調查 | M10: =N10 -> 4 | N10: =COUNTIF(H:H,L10) -> 4
A11: 10 | B11: 主題節目 | C11: 陳樂晞 | D11: V | E11: 6HKG | F11: Random | H11: A3 機電2 | J11: A10 | K11: 香港警務處 - 國家安全處(NSD) | L11: A10 Police-國安 | M11: =N11 -> 5 | N11: =COUNTIF(H:H,L11) -> 5
A12: 11 | B12: 主題節目 | C12: 黃紀靖 | D12: V | E12: 82HKG | F12: Random | H12: A3 機電2 | J12: A11 | K12: 香港警務處 - 交通總區(T HKI - SSP) 1130-1630 | L12: A11 Police-交通 | M12: 3 | N12: =COUNTIF(H:H,L12) -> 3
A13: 12 | B13: 主題節目 | F13: Random | H13: A3 機電2 | J13: A12 | K13: 香港警務處 - 鑑證科(IB / CSI) | L13: A12 Police-鑑證 | M13: =N13 -> 5 | N13: =COUNTIF(H:H,L13) -> 5
A14: 13 | B14: 主題節目 | C14: 馮昊新 | D14: V | E14: 46EKR | F14: Random | H14: A4 機電3 | J14: B1 | K14: 香港島青年聯會 | L14: B1 青年聯會 | M14: 3 | N14: =COUNTIF(H:H,L14) -> 4
A15: 14 | B15: 主題節目 | C15: 李沛埕 | D15: V | E15: 147HKG | F15: Random | H15: A4 機電3 | J15: B2 | K15: 港島童軍射藝會 | L15: B2 箭會 | M15: 4 | N15: =COUNTIF(H:H,L15) -> 4
A16: 15 | B16: 主題節目 | F16: Random | H16: A4 機電3 | J16: B3 | K16: 港島地域 - 深資童軍議會 / 港島南區 | L16: B3 VentureC | M16: 5 | N16: =COUNTIF(H:H,L16) -> 5
A17: 16 | B17: 主題節目 | F17: Random | H17: A4 機電3 | J17: C1 | K17: 港島童軍氣槍射擊會 | L17: C1 槍會 | M17: Nil | N17: =COUNTIF(H:H,L17) -> 4
A18: 17 | B18: 主題節目 | F18: Random | H18: A4 機電3 | J18: C2 | K18: 港島地域 - 航空活動 | L18: C2 Air | M18: 7 | N18: =COUNTIF(H:H,L18) -> 7
A19: 18 | B19: 主題節目 | F19: 午餐時間無需當值 | H19: A4 機電3 | J19: C3 | K19: 香港航天學會 - 航天、航空 | L19: C3 航天學會 | M19: 14 | N19: =COUNTIF(H:H,L19) -> 14
A20: 19 | B20: 主題節目 | C20: 高敏儀 | D20: V | E20: 161HKG | F20: Random | H20: A5 機電4 | J20: C4 | K20: 中國香港東區無人機協會 - 無人機體驗 | L20: C4 無人機 | M20: 19 | N20: =COUNTIF(H:H,L20) -> 19
A21: 20 | B21: 主題節目 | C21: 何卓茵 | D21: V | E21: 161HKG | F21: Random | H21: A5 機電4 | J21: D1 | K21: 港島地域 - 發展部 | M21: Pannie | N21: =COUNTIF(H:H,L21) -> 0
A22: 21 | B22: 主題節目 | C22: 何祉鋆 | D22: V | E22: 161HKG | F22: Random | H22: A5 機電4 | J22: D2 | K22: 港島地域 - 社區參與及服務1 | M22: Pannie | N22: =COUNTIF(H:H,L22) -> 0
A23: 22 | B23: 主題節目 | C23: 伍恩孝 | D23: V | E23: 161HKG | F23: Random | H23: A5 機電4 | J23: D3 | K23: 港島地域 - 社區參與及服務2 | M23: Pannie | N23: =COUNTIF(H:H,L23) -> 0
A24: 23 | B24: 主題節目 | C24: 李漢宏 | D24: V | E24: 161HKG | F24: Random | H24: A5 機電4 | J24: D4 | K24: 港島地域 - 灣仔區 - 社區參與章1 | L24: D4 WCH-社參 1 | M24: 6 | N24: =COUNTIF(H:H,L24) -> 6
A25: 24 | B25: 主題節目 | C25: NA | F25: 午餐時間無需當值 | H25: A6 Police-反恐 | J25: D5 | K25: 港島地域 - 灣仔區 - 社區參與章2 | L25: D5 WCH-社參 2 | M25: 6 | N25: =COUNTIF(H:H,L25) -> 6
A26: 25 | B26: 主題節目 | C26: NA | F26: 午餐時間無需當值 | H26: A6 Police-反恐 | J26: E1 | K26: 港島地域 - 維多利亞城區 - 精神健康章 | L26: E1 VIC-精神健康 | M26: 5 | N26: =COUNTIF(H:H,L26) -> 5
A27: 26 | B27: 主題節目 | C27: NA | F27: 午餐時間無需當值 | H27: A6 Police-反恐 | J27: E2 | K27: 港島地域 - 維多利亞城區 - 公共衞生章 | L27: E2 VIC-公共衛生 | M27: 5 | N27: =COUNTIF(H:H,L27) -> 5
A28: 27 | B28: 主題節目 | C28: NA | F28: 午餐時間無需當值 | H28: A6 Police-反恐 | J28: E3 | K28: Listening Ears | L28: E3 Listening Ear | M28: 2 | N28: =COUNTIF(H:H,L28) -> 2
A29: 28 | B29: 主題節目 | C29: NA | F29: 午餐時間無需當值 | H29: A7 Police-網絡 | J29: F1 | K29: 港島童軍生態小組 | L29: F1 生態 | M29: 6 | N29: =COUNTIF(H:H,L29) -> 6
A30: 29 | B30: 主題節目 | C30: NA | F30: 午餐時間無需當值 | H30: A7 Police-網絡 | J30: F2 | K30: 港島童軍章會 | L30: F2 章會 | M30: 6 | N30: =COUNTIF(H:H,L30) -> 6
A31: 30 | B31: 主題節目 | C31: NA | F31: 午餐時間無需當值 | H31: A7 Police-網絡 | J31: F3 | K31: 港島童軍天文會 | L31: F3 天文會 | M31: Nil | N31: =COUNTIF(H:H,L31) -> 6
A32: 31 | B32: 主題節目 | C32: NA | F32: 午餐時間無需當值 | H32: A7 Police-網絡 | J32: F4 | K32: 港島童軍先鋒工程會 | L32: F4 先鋒會 | M32: 6 | N32: =COUNTIF(H:H,L32) -> 6
A33: 32 | B33: 主題節目 | C33: NA | F33: Random | H33: A8 Police-NB | J33: F5 | K33: 港島地域童軍樂隊 | L33: F5 Band | M33: 30 | N33: =COUNTIF(H:H,L33) -> 30
A34: 33 | B34: 主題節目 | C34: NA | F34: Random | H34: A8 Police-NB | J34: F6 | K34: 港島童軍皮藝會 | L34: F6 皮會 | M34: 6 | N34: =COUNTIF(H:H,L34) -> 6
A35: 34 | B35: 主題節目 | C35: NA | F35: Random | H35: A9 Police-毒品調查 | M35: =SUM(M2:M34) -> 171 | N35: =SUM(N2:N34) -> 191
A36: 35 | B36: 主題節目 | C36: NA | F36: Random | H36: A9 Police-毒品調查
A37: 36 | B37: 主題節目 | C37: NA | F37: Random | H37: A9 Police-毒品調查
A38: 37 | B38: 主題節目 | C38: NA | F38: Random | H38: A9 Police-毒品調查
A39: 38 | B39: 主題節目 | C39: NA | F39: Random | H39: A10 Police-國安
A40: 39 | B40: 主題節目 | C40: NA | F40: Random | H40: A10 Police-國安 | K40: B2 箭會 cut 1 飯
...

Sheet 會操典禮
B1: 組別 | C1: 中文姓名 | D1: 童軍職位 (L,R,V,S) | E1: 所屬旅團 (地域幹部請填寫職位) | F1: 午餐選擇 | G1: 電郵地址(寄發感謝狀用) | H1: Remarks | I1: For core committee only
A2: 1 | B2: 會操典禮 | C2: 張佳良 | D2: L | E2: RS/HKIR | F2: 嘉賓自助午餐(只限總監級) | I2: 副主席(會操及典禮)
A3: 2 | B3: 會操典禮 | C3: 李懷恩 | D3: L | E3: DDC/CHW | F3: B 鹹蛋蒸肉餅飯 配菜 | I3: 總主任（典禮）
A4: 3 | B4: 會操典禮 | C4: 黃凱琳 | D4: L | F4: Random | I4: 典禮統籌主任
A5: 4 | B5: 會操典禮 | C5: 林雋逸 | D5: L | E5: ADC/CHW | F5: B 鹹蛋蒸肉餅飯 配菜 | G5: mattlam@268hkg.org | I5: 優異旅團統籌主任
A6: 5 | B6: 會操典禮 | C6: 馮玉成 | D6: L | F6: A 柱侯蘿蔔牛腩飯 配菜 | I6: 獎勵統籌主任
A7: 6 | B7: 會操典禮 | C7: 范紫晴 | D7: L | F7: Random | I7: 司儀統籌主任
A8: 7 | B8: 會操典禮 | C8: 林卓衡 | D8: L | F8: Random | I8: 司儀統籌主任
B9: 會操典禮 | C9: 莊鎵漩 | D9: V | E9: AHQ | F9: B 鹹蛋蒸肉餅飯 配菜
A10: 8 | B10: 會操典禮 | C10: 甄蘊而 | D10: V | F10: A 柱侯蘿蔔牛腩飯 配菜
A11: 9 | B11: 會操典禮 | C11: 談煒亮 | D11: L | E11: ADC/CHW | F11: A 柱侯蘿蔔牛腩飯 配菜
A12: 10 | B12: 會操典禮 | C12: 梁文澧 | D12: L | E12: ADC/SKW | F12: 小食餐盒 | G12: adc.rover@skwscout.org.hk | I12: 總主任（會操）
A13: 11 | B13: 會操典禮 | C13: 黃志樂 | D13: L | F13: 小食餐盒 | I13: 步操顧問
A14: 12 | B14: 會操典禮 | C14: 王明灝 | D14: L | F14: 小食餐盒 | I14: 步操統籌主任
A15: 13 | B15: 會操典禮 | C15: 林祥俊 | D15: L | F15: 小食餐盒 | I15: 步操統籌主任
A16: 14 | B16: 會操典禮 | C16: 文志韜 | D16: L | F16: 小食餐盒
A17: 15 | B17: 會操典禮 | C17: 陳民寶 | D17: L | F17: 小食餐盒
A18: 16 | B18: 會操典禮 | C18: 吳冠達 | D18: L | F18: 小食餐盒
A19: 17 | B19: 會操典禮 | C19: 馬旌愷 | D19: L | F19: 小食餐盒
A20: 18 | B20: 會操典禮 | C20: 黃澍斌 | D20: L | F20: 小食餐盒
A21: 19 | B21: 會操典禮 | C21: 謝浩俊 | D21: L | F21: 小食餐盒
A22: 20 | B22: 會操典禮 | C22: 鄭志偉 | D22: L | F22: 小食餐盒
A23: 21 | B23: 會操典禮 | C23: 游冠文 | D23: L | F23: 小食餐盒
A24: 22 | B24: 會操典禮 | C24: 駱甯宜 | D24: L | F24: 小食餐盒
A25: 23 | B25: 會操典禮 | C25: 胡志偉 | D25: L | F25: 小食餐盒
A26: 24 | B26: 會操典禮 | C26: 儀仗隊 01 | F26: 小食餐盒
A27: 25 | B27: 會操典禮 | C27: 儀仗隊 02 | F27: 小食餐盒
A28: 26 | B28: 會操典禮 | C28: 儀仗隊 03 | F28: 小食餐盒
A29: 27 | B29: 會操典禮 | C29: 儀仗隊 04 | F29: 小食餐盒
A30: 28 | B30: 會操典禮 | C30: 儀仗隊 05 | F30: 小食餐盒
A31: 29 | B31: 會操典禮 | C31: 儀仗隊 06 | F31: 小食餐盒
A32: 30 | B32: 會操典禮 | C32: 儀仗隊 07 | F32: 小食餐盒
A33: 31 | B33: 會操典禮 | C33: 儀仗隊 08 | F33: 小食餐盒
A34: 32 | B34: 會操典禮 | C34: 儀仗隊 09 | F34: 小食餐盒
A35: 33 | B35: 會操典禮 | C35: 儀仗隊 10 | F35: 小食餐盒
A36: 34 | B36: 會操典禮 | C36: 儀仗隊 11 | F36: 小食餐盒
A37: 35 | B37: 會操典禮 | C37: 儀仗隊 12 | F37: 小食餐盒
... A41: 39 | B41: 會操典禮 | C41: 儀仗隊 16 | F41: 小食餐盒
D42: A | E42: =COUNTIF(F:F,"A*") -> 3
D43: B | E43: =COUNTIF(F:F,"B*") -> 3
...

Sheet 服務
B1: 組別 | C1: 中文姓名 | D1: 童軍職位 (L,R,V,S) | E1: 所屬旅團 (地域幹部請填寫職位) | F1: 午餐選擇 | G1: 電郵地址(寄發感謝狀用) | H1: Remarks | I1: For core committee only
A2: 1 | B2: 服務與發展 | C2: 黎姵伶 | D2: L | E2: ARHQC | F2: B 鹹蛋蒸肉餅飯 配菜 | G2: pannielai@hkirscout.org.hk | I2: 副主席(服務及發展)
A3: 2 | B3: 服務與發展 | C3: 李卓琪 | D3: L | E3: RHQC | F3: B 鹹蛋蒸肉餅飯 配菜 | G3: reginali@hkirscout.org.hk | I3: 總主任(服務及發展)
A4: 3 | B4: 服務與發展 | C4: 郭成威 | D4: R | F4: C 滷水雞髀拼紅腸飯 配菜 | G4: g2832454514@gmail.com | I4: 機構聯絡主任
A5: 4 | B5: 服務與發展 | C5: 楊煒儀 | D5: L | E5: 2nd HKG | F5: B 鹹蛋蒸肉餅飯 配菜 | G5: touzai023@gmail.com
A6: 5 | B6: 服務與發展 | C6: 黃泳珊 | D6: L | E6: 175th HKG | F6: B 鹹蛋蒸肉餅飯 配菜 | G6: c29050@yahoo.com.hk
A7: 6 | B7: 服務與發展 | C7: 李國文 | D7: L | E7: RHQC | F7: A 柱侯蘿蔔牛腩飯 配菜
A8: 7 | B8: 服務與發展 | C8: 黎仲豪 | D8: L | E8: ARHQC | F8: C 滷水雞髀拼紅腸飯 配菜
A9: 8 | B9: 服務與發展 | C9: 鄭善茵 | D9: L | E9: HKIR RS | F9: B 鹹蛋蒸肉餅飯 配菜
A10: 9 | B10: 服務與發展 | C10: 觀塘循道衛理 | D10: L | E10: NGO | F10: A 柱侯蘿蔔牛腩飯 配菜
A11: 10 | B11: 服務與發展 | C11: 觀塘循道衛理 | D11: L | E11: NGO | F11: C 滷水雞髀拼紅腸飯 配菜
A12: 11 | B12: 服務與發展 | C12: 張惠敏 | D12: L | E12: ARHQC | F12: 嘉賓自助午餐(只限總監級/副主席) | G12: np1095th@yahoo.com.hk
A13: 12 | B13: 服務與發展 | C13: 吳宇森 | D13: L | E13: HKIR RS | F13: A 柱侯蘿蔔牛腩飯 配菜 | G13: ngyusum99@gmail.com
A14: 13 | B14: 服務與發展 | C14: 潘日朗 | D14: L | E14: 5th HKG | F14: A 柱侯蘿蔔牛腩飯 配菜 | G14: brianpoon1113@gmail.com
A15: 14 | B15: 服務與發展 | C15: 袁宇靖 | D15: R | E15: RoverC | F15: C 滷水雞髀拼紅腸飯 配菜 | G15: duncanyuen@gmail.com
D16: A | E16: =COUNTIF(F:F,"A*") -> 4
D17: B | E17: =COUNTIF(F:F,"B*") -> 5
D18: C | E18: =COUNTIF(F:F,"C*") -> 4
D19: D | E19: =COUNTIF(F:F,"D*") -> 0
D20: Buffet | E20: =COUNTIF(F:F,"嘉*") -> 1

Sheet 協調
B1: 組別 | C1: 中文姓名 | E1: 童軍職位 (L,R,V,S) | F1: 所屬旅團 (地域幹部請填寫職位) | G1: 午餐選擇 | H1: 電郵地址(寄發感謝狀用) | I1: Remarks | J1: For core committee only
A2: 1 | B2: 協調 | C2: 羅添駿 | E2: L | F2: 1257HKG | G2: Random | J2: 副主席(協調)
A3: 2 | B3: 協調 | C3: 鍾偉志 | E3: L | F3: RHQC | G3: 嘉賓自助午餐(只限總監級) | J3: 總主任（協調）
A4: 3 | B4: 協調 | C4: 馬一波 | E4: L | F4: 1257HKG | G4: Random | J4: 場地佈置主任
A5: 4 | B5: 協調 | C5: 吳卓藍 | F5: 1257HKG | G5: Random | J5: 膳食主任
A6: 5 | B6: 協調 | C6: 郭慧敏 | F6: 1257HKG | G6: Random | J6: 後勤主任
A7: 6 | B7: 協調 | C7: 施珍淇 | F7: 1257HKG | G7: Random | J7: 物資主任
A8: 7 | B8: 協調 | C8: 黃嘉恩 | E8: L | F8: RHQC | G8: 嘉賓自助午餐(只限總監級) | J8: 總主任(協調）
A9: 8 | B9: 協調 | C9: 布瀚文 | E9: L | F9: 1257HKG | G9: Random | J9: 秩序主任
A10: 9 | B10: 協調 | C10: 鄺逸俊 | E10: L | F10: 1257HKG | G10: Random | J10: 交通管制主任
A11: 10 | B11: 協調 | C11: 李思諭 | E11: L | F11: 1257HKG | G11: Random | J11: 物流運輸主任
A12: 11 | B12: 協調 | C12: 許嘉琪 | F12: 1257HKG | G12: Random
A13: 12 | B13: 協調 | C13: 楊子軒 | F13: 1257HKG | G13: Random
A14: 13 | B14: 協調 | C14: 李晞朗 | F14: 1257HKG | G14: Random
A15: 14 | B15: 協調 | C15: 吳偉傑 | F15: 1257HKG | G15: Random
A16: 15 | B16: 協調 | C16: 麥天恩 | F16: 1257HKG | G16: Random
A17: 16 | B17: 協調 | C17: 譚逸朗 | F17: 1257HKG | G17: Random
A18: 17 | B18: 協調 | C18: 葉瑞恩 | E18: L | F18: RS | G18: Random
E19: A | F19: =COUNTIF(G:G,"A*") -> 0
E20: B | F20: =COUNTIF(G:G,"B*") -> 0
E21: C | F21: =COUNTIF(G:G,"C*") -> 0
E22: D | F22: =COUNTIF(G:G,"D*") -> 0
E23: Random | F23: =COUNTIF(G:G,"Random") -> 15
E24: Buffet | F24: =COUNTIF(G:G,"嘉*") -> 2
C26: 袁宇靖 moved to 服務

Sheet 行政
B1: 組別 | C1: 中文姓名 | D1: 童軍職位 (L,R,V,S) | E1: 所屬旅團 (地域幹部請填寫職位) | F1: 午餐選擇 | G1: 電郵地址(寄發感謝狀用) | H1: Remarks | I1: For core committee only
A2: 1 | B2: 行政 | C2: 徐嘉皓 | D2: L | E2: DCSL/SKW | F2: A 柱侯蘿蔔牛腩飯 配菜 | G2: alantsui2005@gmail.com | I2: 副主席(行政)
A3: 2 | B3: 行政 | C3: 文幹皓 | D3: L | E3: DDC/SKW | F3: 嘉賓自助午餐(只限總監級) | G3: ddc.admin@skwscout.org.hk | I3: 總主任(運作)
A4: 3 | B4: 行政 | C4: 莫穎民 | D4: L | E4: 82HKG | F4: A 柱侯蘿蔔牛腩飯 配菜 | G4: playerkousas@hotmail.com | I4: 總主任(行政)
A5: 4 | B5: 行政 | C5: 陳銘彥 | D5: L | E5: 50HKG | F5: 小食餐盒 | G5: dc@skwscout.org.hk | I5: 旅團報到主任
A6: 5 | B6: 行政 | C6: 何仲康 | D6: L | E6: ADC/SKW | F6: A 柱侯蘿蔔牛腩飯 配菜 | G6: adc.venture@skwscout.org.hk | I6: 紀念品主任
A7: 6 | B7: 行政 | C7: 蔡天欣 | D7: L | E7: SKW | F7: B 鹹蛋蒸肉餅飯 配菜 | G7: tinyan.choi@gmail.com | I7: 財政主任
A8: 7 | B8: 行政 | C8: 葉永全 | D8: L | E8: 206HKG | F8: B 鹹蛋蒸肉餅飯 配菜 | G8: clive206@yahoo.com.hk
A9: 8 | B9: 行政 | C9: 李泳希 | D9: S | E9: 206HKG | F9: C 滷水雞髀拼紅腸飯 配菜 | G9: tinyan.choi@gmail.com
A10: 9 | B10: 行政 | C10: 李俊熹 | D10: S | E10: 206HKG | F10: C 滷水雞髀拼紅腸飯 配菜 | G10: tinyan.choi@gmail.com
A11: 10 | B11: 行政 | C11: 何緯業 | D11: V | E11: 206HKG | F11: C 滷水雞髀拼紅腸飯 配菜 | G11: tinyan.choi@gmail.com
A12: 11 | B12: 行政 | C12: 溫智誼 | D12: S | E12: 206HKG | F12: C 滷水雞髀拼紅腸飯 配菜 | G12: tinyan.choi@gmail.com
A13: 12 | B13: 行政 | C13: 危曉晴 | D13: S | E13: 206HKG | F13: 小食餐盒 | G13: tinyan.choi@gmail.com
A14: 13 | B14: 行政 | C14: 朱彥南 | D14: S | E14: 206HKG | F14: 小食餐盒 | G14: tinyan.choi@gmail.com
A15: 14 | B15: 行政 | C15: 陳日雪 | D15: S | E15: 206HKG | F15: 小食餐盒 | G15: tinyan.choi@gmail.com
A16: 15 | B16: 行政 | C16: 陳后嘉 | D16: S | E16: 206HKG | F16: 小食餐盒 | G16: tinyan.choi@gmail.com
A17: 16 | B17: 行政 | C17: 鄭樂勤 | D17: S | E17: 206HKG | F17: 小食餐盒 | G17: 206hkg@hkirscout.org.hk
A18: 17 | B18: 行政 | C18: 林蓓虹 | D18: S | E18: 206HKG | F18: 小食餐盒 | G18: 206hkg@hkirscout.org.hk
A19: 18 | B19: 行政 | C19: 陳培芬 | D19: S | E19: 206HKG | F19: 小食餐盒 | G19: 206hkg@hkirscout.org.hk
... A26: 25 | B26: 行政 | C26: 施純龍 | D26: S | E26: 149HKG | F26: Random | G26: joseph8149@gmail.com
D27: A | E27: =COUNTIF(F:F,"A*") -> 3
D28: B | E28: =COUNTIF(F:F,"B*") -> 2
D29: C | E29: 4
D30: D | E30: =COUNTIF(F:F,"D*") -> 0
D31: Random | E31: =COUNTIF(F:F,"Random") -> 7
D32: 小食 | E32: =COUNTIF(F:F,"小*") -> 8
D33: Buffet | E33: =COUNTIF(F:F,"嘉*") -> 1

Sheet OrgC
B1: 港島童軍繽紛日2026 組織架構圖 | N1: Establishment | O1: Strength
B3: 顧問 | D3: 副主席 （會操及典禮） | F3: 總主任 （會操） | H3: 步操統籌主任 | I3: 會操司令員 | J3: 會操顧問 | N3: =COUNTA(D3:J3) -> 5 | O3: =COUNTA(D4:J4) -> 3
B4: 黃偉安 何家騏 | D4: 張佳良 | F4: 梁文澧 | J4: 黃志樂
B6: 主席 | F6: 總主任 （典禮） | H6: 典禮統籌主任 | I6: 優異旅團 統籌主任 | J6: 獎勵統籌主任 | K6: 司儀統籌主任 | N6: =COUNTA(F6:K6) -> 5 | O6: =COUNTA(F7:K7) -> 5
B7: 朱家聰 | F7: 李懷恩 | H7: 黃凱琳 | I7: 林雋逸 | J7: 馮玉成 | K7: 范紫晴, 林卓衡
B9: 執行副主席 | D9: 副主席 （主題節目） | F9: 總主任 （主題節目） | H9: 節目主任 （1） | I9: 節目主任 （2） | J9: 節目主任 （3） | K9: 節目主任 （4） | L9: 節目主任 （5） | N9: =COUNTA(D9:L9) -> 7 | O9: =COUNTA(D10:L10) -> 7
B10: 袁可秀 | D10: 周恒晉 | F10: 仇紹謙 | H10: 何令勤 | I10: 陳鋑羲 | J10: 張宏剛 | K10: 羅卓華 | L10: 李庭甄
D12: 副主席 （品牌推廣） | F12: 總主任 （品牌推廣） | H12: 設計主任 | I12: 宣傳主任 | J12: 社交媒體主任 | K12: 拍攝/攝錄 統籌主任 | N12: =COUNTA(D12:K12) -> 6 | O12: =COUNTA(D13:K13) -> 6
D13: 何嘉駿 | F13: 李沛豪 | H13: 方敏聰 | I13: 陳鈞瀚 | J13: 徐士奇 | K13: 林耀鏘
D15: 副主席 （嘉賓接待） | F15: 總主任 （嘉賓接待） | H15: 嘉賓接待主任 | I15: 交通主任 | J15: 嘉賓支援主任 | N15: =COUNTA(D15:J15) -> 5 | O15: =COUNTA(D16:J16) -> 5
D16: 曾麗珊 | F16: 張嘉政 | H16: 黃培芳 | I16: 張敬浩 | J16: 朱浩銘
D18: 副主席 （協調） | F18: 總主任 （協調） | H18: 場地佈置主任 | I18: 膳食主任 | J18: 後勤主任 | K18: 物資主任 | N18: =COUNTA(D18:K18) -> 6 | O18: =COUNTA(D19:K19) -> 6
D19: 羅添駿 | F19: 鍾偉志 | H19: 馬一波 | I19: 吳卓藍 | J19: 郭慧敏 | K19: 施珍淇
F21: 總主任 （協調） | H21: 秩序主任 | I21: 交通管制主任 | J21: 物流運輸主任 | N21: =COUNTA(F21:J21) -> 4 | O21: =COUNTA(F22:J22) -> 4
F22: 黃嘉恩 | H22: 布瀚文 | I22: 鄺逸俊 | J22: 李思諭 | K22: 袁宇靖
D24: 副主席 （服務及發展） | F24: 總主任 （服務及發展） | H24: 服務主任 | I24: 發展主任 | J24: 募捐主任 | K24: 機構聯絡主任 | N24: =COUNTA(D24:K24) -> 6 | O24: =COUNTA(D25:K25) -> 3
D25: 黎姵伶 | F25: 李卓琪 | H25: 郭成威
D27: 副主席 （行政） | F27: 總主任 (運作) | H27: 旅團報到主任 | I27: 紀念品主任 | J27: 危機處理主任 | N27: =COUNTA(D27:J27) -> 5 | O27: =COUNTA(D28:J28) -> 5
D28: 徐嘉皓 | F28: 文幹皓 | H28: 陳銘彥 | I28: 何仲康 | J28: 何家騏
F30: 總主任 (行政) | H30: 行政主任 | I30: 參事主任 | J30: 財政主任 | N30: =COUNTA(F30:J30) -> 4 | O30: =COUNTA(F31:J31) -> 2
F31: 莫穎民 | J31: 蔡天欣
N33: =SUM(N1:N32) -> 53 | O33: =SUM(O1:O32) -> 46 | P33: =O33/N33 -> 0.86792453

Sheet para
A1: EAT
A2: 嘉賓自助午餐(只限總監級/副主席) | B2: 嘉賓自助午餐(只限總監級)
A3: A 柱侯蘿蔔牛腩飯 配菜 | B3: Random
A4: B 鹹蛋蒸肉餅飯 配菜 | B4: D (素)翠玉瓜雲耳炒野菌
A5: C 滷水雞髀拼紅腸飯 配菜 | B5: 午餐時間無需當值
A6: D (素)翠玉瓜雲耳炒野菌
A7: Random
A8: 午餐時間無需當值
A9: 小食餐盒
